Failure # 1 (occurred at 2023-04-03_23-08-42)
Traceback (most recent call last):
  File "/home/ga_aiot/anaconda3/envs/finrl/lib/python3.8/site-packages/ray/tune/execution/ray_trial_executor.py", line 1276, in get_next_executor_event
    future_result = ray.get(ready_future)
  File "/home/ga_aiot/anaconda3/envs/finrl/lib/python3.8/site-packages/ray/_private/client_mode_hook.py", line 105, in wrapper
    return func(*args, **kwargs)
  File "/home/ga_aiot/anaconda3/envs/finrl/lib/python3.8/site-packages/ray/_private/worker.py", line 2382, in get
    raise value
ray.exceptions.RayActorError: The actor died because of an error raised in its creation task, [36mray::PPO.__init__()[39m (pid=2157, ip=172.28.231.77, repr=PPO)
  File "/home/ga_aiot/anaconda3/envs/finrl/lib/python3.8/site-packages/ray/rllib/evaluation/worker_set.py", line 240, in _setup
    self.add_workers(
  File "/home/ga_aiot/anaconda3/envs/finrl/lib/python3.8/site-packages/ray/rllib/evaluation/worker_set.py", line 614, in add_workers
    raise result.get()
  File "/home/ga_aiot/anaconda3/envs/finrl/lib/python3.8/site-packages/ray/rllib/utils/actor_manager.py", line 477, in __fetch_result
    result = ray.get(r)
ray.exceptions.RayActorError: The actor died because of an error raised in its creation task, [36mray::RolloutWorker.__init__()[39m (pid=2289, ip=172.28.231.77, repr=<ray.rllib.evaluation.rollout_worker.RolloutWorker object at 0x7fef367d6d60>)
  File "/home/ga_aiot/anaconda3/envs/finrl/lib/python3.8/site-packages/gymnasium/envs/registration.py", line 569, in make
    _check_version_exists(ns, name, version)
  File "/home/ga_aiot/anaconda3/envs/finrl/lib/python3.8/site-packages/gymnasium/envs/registration.py", line 219, in _check_version_exists
    _check_name_exists(ns, name)
  File "/home/ga_aiot/anaconda3/envs/finrl/lib/python3.8/site-packages/gymnasium/envs/registration.py", line 197, in _check_name_exists
    raise error.NameNotFound(
gymnasium.error.NameNotFound: Environment finrl doesn't exist. 

During handling of the above exception, another exception occurred:

[36mray::RolloutWorker.__init__()[39m (pid=2289, ip=172.28.231.77, repr=<ray.rllib.evaluation.rollout_worker.RolloutWorker object at 0x7fef367d6d60>)
  File "/home/ga_aiot/anaconda3/envs/finrl/lib/python3.8/site-packages/ray/rllib/evaluation/rollout_worker.py", line 607, in __init__
    self.env = env_creator(copy.deepcopy(self.env_context))
  File "/home/ga_aiot/anaconda3/envs/finrl/lib/python3.8/site-packages/ray/rllib/env/utils.py", line 178, in _gym_env_creator
    raise EnvError(ERR_MSG_INVALID_ENV_DESCRIPTOR.format(env_descriptor))
ray.rllib.utils.error.EnvError: The env string you provided ('finrl') is:
a) Not a supported/installed environment.
b) Not a tune-registered environment creator.
c) Not a valid env class string.

Try one of the following:
a) For Atari support: `pip install gym[atari] autorom[accept-rom-license]`.
   For VizDoom support: Install VizDoom
   (https://github.com/mwydmuch/ViZDoom/blob/master/doc/Building.md) and
   `pip install vizdoomgym`.
   For PyBullet support: `pip install pybullet`.
b) To register your custom env, do `from ray import tune;
   tune.register('[name]', lambda cfg: [return env obj from here using cfg])`.
   Then in your config, do `config['env'] = [name]`.
c) Make sure you provide a fully qualified classpath, e.g.:
   `ray.rllib.examples.env.repeat_after_me_env.RepeatAfterMeEnv`

During handling of the above exception, another exception occurred:

[36mray::PPO.__init__()[39m (pid=2157, ip=172.28.231.77, repr=PPO)
  File "/home/ga_aiot/anaconda3/envs/finrl/lib/python3.8/site-packages/ray/rllib/algorithms/algorithm.py", line 445, in __init__
    super().__init__(
  File "/home/ga_aiot/anaconda3/envs/finrl/lib/python3.8/site-packages/ray/tune/trainable/trainable.py", line 169, in __init__
    self.setup(copy.deepcopy(self.config))
  File "/home/ga_aiot/anaconda3/envs/finrl/lib/python3.8/site-packages/ray/rllib/algorithms/algorithm.py", line 571, in setup
    self.workers = WorkerSet(
  File "/home/ga_aiot/anaconda3/envs/finrl/lib/python3.8/site-packages/ray/rllib/evaluation/worker_set.py", line 192, in __init__
    raise e.args[0].args[2]
ray.rllib.utils.error.EnvError: The env string you provided ('finrl') is:
a) Not a supported/installed environment.
b) Not a tune-registered environment creator.
c) Not a valid env class string.

Try one of the following:
a) For Atari support: `pip install gym[atari] autorom[accept-rom-license]`.
   For VizDoom support: Install VizDoom
   (https://github.com/mwydmuch/ViZDoom/blob/master/doc/Building.md) and
   `pip install vizdoomgym`.
   For PyBullet support: `pip install pybullet`.
b) To register your custom env, do `from ray import tune;
   tune.register('[name]', lambda cfg: [return env obj from here using cfg])`.
   Then in your config, do `config['env'] = [name]`.
c) Make sure you provide a fully qualified classpath, e.g.:
   `ray.rllib.examples.env.repeat_after_me_env.RepeatAfterMeEnv`

